#VRML_SIM R2023b utf8

EXTERNPROTO "https://raw.githubusercontent.com/cyberbotics/webots/R2023b/projects/objects/backgrounds/protos/TexturedBackground.proto"
EXTERNPROTO "https://raw.githubusercontent.com/cyberbotics/webots/R2023b/projects/objects/backgrounds/protos/TexturedBackgroundLight.proto"
EXTERNPROTO "https://raw.githubusercontent.com/cyberbotics/webots/R2023b/projects/objects/floors/protos/RectangleArena.proto"

WorldInfo {
}
Viewpoint {
  orientation 0.08845306700746274 0.9556712932412861 -0.2808352438913265 0.8834595302047046
  position -1.469951099908313 -0.8816821438426692 2.035961081710581
}
TexturedBackground {
}
TexturedBackgroundLight {
}
RectangleArena {
  floorSize 6 4
  floorAppearance PBRAppearance {
    baseColor 0.313726 0.619608 0.184314
    metalness 0
  }
}
DEF BALL_AREA Pose {
  translation -1.8 -8.44714e-06 0.001
  rotation 0 0 1 0.785403
  children [
    Shape {
      appearance PBRAppearance {
        metalness 0
      }
      geometry Plane {
        size 0.85 0.85
      }
    }
  ]
}
DEF START_AREA_E Pose {
  translation 0 -1.55 0.0015
  rotation 0 0 -1 -5.307179586466759e-06
  children [
    Shape {
      appearance PBRAppearance {
        baseColor 0 0.333333 1
        metalness 0
      }
      geometry Plane {
        size 0.9 0.9
      }
    }
  ]
}
DEF START_AREA_B Pose {
  translation 0 -1.55 0.002
  rotation 0 0 -1 -5.307179586466759e-06
  children [
    Shape {
      appearance PBRAppearance {
        baseColor 0 1 1
        metalness 0
      }
      geometry Plane {
        size 0.7 0.7
      }
    }
  ]
}
DEF TOWER_AREA Pose {
  translation 1.25 -3.39657e-06 0.001
  rotation 0 0 -1 -5.307179586466759e-06
  children [
    Shape {
      appearance PBRAppearance {
        baseColor 0.996078 0.819608 0.254902
        metalness 0
      }
      geometry Plane {
        size 3.5 4
      }
    }
  ]
}
DEF TOWERS Group {
  children [
    Solid {
      translation 2.69 0 0
      children [
        DEF TOWER Shape {
          appearance PBRAppearance {
            metalness 0
          }
          geometry Mesh {
            url [
              "Tower.obj"
            ]
          }
        }
      ]
      boundingObject USE TOWER
      locked TRUE
    }
    Solid {
      translation 2.69 -0.75 0
      children [
        DEF TOWER Shape {
          appearance PBRAppearance {
            metalness 0
          }
          geometry Mesh {
            url [
              "Tower.obj"
            ]
          }
        }
      ]
      name "solid(3)"
      boundingObject USE TOWER
    }
    Solid {
      translation 2.69 -1.5 0
      children [
        DEF TOWER Shape {
          appearance PBRAppearance {
            metalness 0
          }
          geometry Mesh {
            url [
              "Tower.obj"
            ]
          }
        }
      ]
      name "solid(4)"
      boundingObject USE TOWER
      locked TRUE
    }
    Solid {
      translation 2.69 0.75 0
      children [
        DEF TOWER Shape {
          appearance PBRAppearance {
            metalness 0
          }
          geometry Mesh {
            url [
              "Tower.obj"
            ]
          }
        }
      ]
      name "solid(1)"
      boundingObject USE TOWER
      locked TRUE
    }
    Solid {
      translation 2.69 1.5 0
      children [
        DEF TOWER Shape {
          appearance PBRAppearance {
            metalness 0
          }
          geometry Mesh {
            url [
              "Tower.obj"
            ]
          }
        }
      ]
      name "solid(2)"
      boundingObject USE TOWER
      locked TRUE
    }
  ]
}
DEF BALLS Group {
  children [
    Solid {
      translation -2.25586 -5.89673e-08 0.0893629950629925
      rotation 0 0 0.9999999999999999 0.7853979999999999
      children [
        DEF BLUE_BALL Shape {
          appearance PBRAppearance {
            baseColor 0.188235 0.498039 0.886275
            metalness 0
          }
          geometry Sphere {
            radius 0.095
          }
        }
      ]
      name "solid(5)"
      boundingObject USE BLUE_BALL
      physics Physics {
      }
    }
    Solid {
      translation -2.11446 -0.141421 0.0893629950629925
      rotation 0 0 0.9999999999999999 0.7853979999999999
      children [
        DEF RED_BALL Shape {
          appearance PBRAppearance {
            baseColor 0.956863 0.211765 0.298039
            metalness 0
          }
          geometry Sphere {
            radius 0.095
          }
        }
      ]
      name "solid(9)"
      boundingObject USE RED_BALL
      physics Physics {
      }
    }
    Solid {
      translation -1.97306 -0.282841 0.0893629950629925
      rotation 0 0 0.9999999999999999 0.7853979999999999
      children [
        DEF BLUE_BALL Shape {
          appearance PBRAppearance {
            baseColor 0.188235 0.498039 0.886275
            metalness 0
          }
          geometry Sphere {
            radius 0.095
          }
        }
      ]
      name "solid(16)"
      boundingObject USE BLUE_BALL
      physics Physics {
      }
    }
    Solid {
      translation -1.83166 -0.424261 0.0893629950629925
      rotation 0 0 0.9999999999999999 0.7853979999999999
      children [
        DEF BLUE_BALL Shape {
          appearance PBRAppearance {
            baseColor 0.188235 0.498039 0.886275
            metalness 0
          }
          geometry Sphere {
            radius 0.095
          }
        }
      ]
      name "solid(20)"
      boundingObject USE BLUE_BALL
      physics Physics {
      }
    }
    Solid {
      translation -2.11446 0.141421 0.0893629950629925
      rotation 0 0 0.9999999999999999 0.7853979999999999
      children [
        DEF RED_BALL Shape {
          appearance PBRAppearance {
            baseColor 0.956863 0.211765 0.298039
            metalness 0
          }
          geometry Sphere {
            radius 0.095
          }
        }
      ]
      name "solid(6)"
      boundingObject USE RED_BALL
      physics Physics {
      }
    }
    Solid {
      translation -1.97306 -4.10327e-08 0.0893629950629925
      rotation 0 0 0.9999999999999999 0.7853979999999999
      children [
        DEF BLUE_BALL Shape {
          appearance PBRAppearance {
            baseColor 0.188235 0.498039 0.886275
            metalness 0
          }
          geometry Sphere {
            radius 0.095
          }
        }
      ]
      name "solid(10)"
      boundingObject USE BLUE_BALL
      physics Physics {
      }
    }
    Solid {
      translation -1.83166 -0.141421 0.0893629950629925
      rotation 0 0 0.9999999999999999 0.7853979999999999
      children [
        DEF RED_BALL Shape {
          appearance PBRAppearance {
            baseColor 0.956863 0.211765 0.298039
            metalness 0
          }
          geometry Sphere {
            radius 0.095
          }
        }
      ]
      name "solid(15)"
      boundingObject USE RED_BALL
      physics Physics {
      }
    }
    Solid {
      translation -1.69026 -0.282841 0.0893629950629925
      rotation 0 0 0.9999999999999999 0.7853979999999999
      children [
        DEF BLUE_BALL Shape {
          appearance PBRAppearance {
            baseColor 0.188235 0.498039 0.886275
            metalness 0
          }
          geometry Sphere {
            radius 0.095
          }
        }
      ]
      name "solid(19)"
      boundingObject USE BLUE_BALL
      physics Physics {
      }
    }
    Solid {
      translation -1.97306 0.282841 0.0893629950629925
      rotation 0 0 0.9999999999999999 0.7853979999999999
      children [
        DEF BLUE_BALL Shape {
          appearance PBRAppearance {
            baseColor 0.188235 0.498039 0.886275
            metalness 0
          }
          geometry Sphere {
            radius 0.095
          }
        }
      ]
      name "solid(7)"
      boundingObject USE BLUE_BALL
      physics Physics {
      }
    }
    Solid {
      translation -1.83166 0.141421 0.0893629950629925
      rotation 0 0 0.9999999999999999 0.7853979999999999
      children [
        DEF RED_BALL Shape {
          appearance PBRAppearance {
            baseColor 0.956863 0.211765 0.298039
            metalness 0
          }
          geometry Sphere {
            radius 0.095
          }
        }
      ]
      name "solid(11)"
      boundingObject USE RED_BALL
      physics Physics {
      }
    }
    Solid {
      translation -1.69026 -4.61033e-07 0.0893629950629925
      rotation 0 0 0.9999999999999999 0.7853979999999999
      children [
        DEF BLUE_BALL Shape {
          appearance PBRAppearance {
            baseColor 0.188235 0.498039 0.886275
            metalness 0
          }
          geometry Sphere {
            radius 0.095
          }
        }
      ]
      name "solid(14)"
      boundingObject USE BLUE_BALL
      physics Physics {
      }
    }
    Solid {
      translation -1.54886 -0.141422 0.0893629950629925
      rotation 0 0 0.9999999999999999 0.7853979999999999
      children [
        DEF RED_BALL Shape {
          appearance PBRAppearance {
            baseColor 0.956863 0.211765 0.298039
            metalness 0
          }
          geometry Sphere {
            radius 0.095
          }
        }
      ]
      name "solid(18)"
      boundingObject USE RED_BALL
      physics Physics {
      }
    }
    Solid {
      translation -1.83166 0.424261 0.0893629950629925
      rotation 0 0 0.9999999999999999 0.7853979999999999
      children [
        DEF BLUE_BALL Shape {
          appearance PBRAppearance {
            baseColor 0.188235 0.498039 0.886275
            metalness 0
          }
          geometry Sphere {
            radius 0.095
          }
        }
      ]
      name "solid(8)"
      boundingObject USE BLUE_BALL
      physics Physics {
      }
    }
    Solid {
      translation -1.69025 0.282841 0.0893629950629925
      rotation 0 0 0.9999999999999999 0.7853979999999999
      children [
        DEF BLUE_BALL Shape {
          appearance PBRAppearance {
            baseColor 0.188235 0.498039 0.886275
            metalness 0
          }
          geometry Sphere {
            radius 0.095
          }
        }
      ]
      name "solid(12)"
      boundingObject USE BLUE_BALL
      physics Physics {
      }
    }
    Solid {
      translation -1.54885 0.141421 0.0893629950629925
      rotation 0 0 0.9999999999999999 0.7853979999999999
      children [
        DEF RED_BALL Shape {
          appearance PBRAppearance {
            baseColor 0.956863 0.211765 0.298039
            metalness 0
          }
          geometry Sphere {
            radius 0.095
          }
        }
      ]
      name "solid(13)"
      boundingObject USE RED_BALL
      physics Physics {
      }
    }
    Solid {
      translation -1.40745 -3.38967e-07 0.0893629950629925
      rotation 0 0 0.9999999999999999 0.7853979999999999
      children [
        DEF BLUE_BALL Shape {
          appearance PBRAppearance {
            baseColor 0.188235 0.498039 0.886275
            metalness 0
          }
          geometry Sphere {
            radius 0.095
          }
        }
      ]
      name "solid(17)"
      boundingObject USE BLUE_BALL
      physics Physics {
      }
    }
  ]
}
Robot {
  translation -5.019145373580788e-07 -1.6609169262920924 0.09368527761061968
  rotation 0.9999999424099653 -0.00032809632659469345 8.679208780633549e-05 0.012375144161225662
  children [
    DEF body Pose {
      children [
        DEF body Shape {
          appearance PBRAppearance {
            roughness 1
            metalness 0
          }
          geometry Box {
            size 0.4 0.25 0.1
          }
        }
        GPS {
          translation 0 0 0.05
          boundingObject USE body
          physics Physics {
          }
        }
      ]
    }
    Pose {
      translation -0.1875 0.25 0
      children [
        Shape {
          appearance PBRAppearance {
            roughness 1
            metalness 0
          }
          geometry Box {
            size 0.025 0.25 0.1
          }
        }
      ]
    }
    Pose {
      translation 0.1875 0.25 0
      children [
        DEF side_arm Shape {
          appearance PBRAppearance {
            roughness 1
            metalness 0
          }
          geometry Box {
            size 0.025 0.25 0.1
          }
        }
      ]
    }
    HingeJoint {
      jointParameters HingeJointParameters {
        position -1.2016490214494921
        anchor -0.226 0.32 -0.025
      }
      device [
        RotationalMotor {
          name "front_left"
        }
      ]
      endPoint Solid {
        translation -0.2255 0.32 -0.025
        rotation -0.49212552942645005 -0.7180691440428325 0.49212718646741116 1.8960953445652469
        children [
          DEF wheel Shape {
            appearance PBRAppearance {
              baseColor 0 0 0
              roughness 1
              metalness 0
            }
            geometry Cylinder {
              height 0.05
              radius 0.075
            }
          }
        ]
        boundingObject USE wheel
        physics DEF wheel_physics Physics {
        }
      }
    }
    HingeJoint {
      jointParameters HingeJointParameters {
        position -1.201649109283436
        anchor 0.226 0.32 -0.025
      }
      device [
        RotationalMotor {
          name "front_right"
        }
      ]
      endPoint Solid {
        translation 0.226 0.32 -0.025
        rotation -0.4921255533243052 -0.718069111286141 0.49212721036534657 1.8960953877905737
        children [
          DEF wheel2 Shape {
            appearance PBRAppearance {
              baseColor 0 0 0
              roughness 1
              metalness 0
            }
            geometry Cylinder {
              height 0.05
              radius 0.075
            }
          }
        ]
        name "solid(1)"
        boundingObject USE wheel2
        physics USE wheel_physics
      }
    }
    HingeJoint {
      jointParameters HingeJointParameters {
        position -1.2016495651515549
        anchor 0.226 -0.075 -0.025
      }
      device [
        RotationalMotor {
          name "right_back"
        }
      ]
      endPoint Solid {
        translation 0.226 -0.075 -0.025
        rotation -0.4923120453811141 -0.7179820131279601 0.492067758339627 1.8957368191819512
        children [
          USE wheel2
        ]
        name "solid(2)"
        boundingObject USE wheel2
        physics USE wheel_physics
      }
    }
    HingeJoint {
      jointParameters HingeJointParameters {
        position -1.201649494369255
        anchor -0.226 -0.075 -0.025
      }
      device [
        RotationalMotor {
          name "left_back"
        }
      ]
      endPoint Solid {
        translation -0.226 -0.075 -0.025
        rotation -0.49231202612004804 -0.7179820395290397 0.4920677390881193 1.895736784334974
        children [
          USE wheel
        ]
        name "solid(3)"
        boundingObject USE wheel
        physics USE wheel_physics
      }
    }
    Pose {
      translation 0.01 0.12 0.325
      children [
        Shape {
          appearance PBRAppearance {
            roughness 1
            metalness 0
          }
          geometry Box {
            size 0.07 0.02 0.75
          }
        }
        DistanceSensor {
          translation 0 0 -0.34
          rotation 0 0 1 1.5708
          name "distance sensor in body"
        }
      ]
    }
    SliderJoint {
      jointParameters JointParameters {
        position -4.949746963320783e-06
        minStop -0.05
        maxStop 0.55
      }
      device [
        LinearMotor {
          name "virtical_arm"
          acceleration 1
          maxForce 200
        }
      ]
      endPoint Solid {
        translation 0 0.134 -0.04400494974696332
        children [
          DEF arm_h Shape {
            appearance PBRAppearance {
              roughness 1
              metalness 0
            }
            geometry Box {
              size 0.345 0.005 0.1
            }
          }
          SliderJoint {
            jointParameters JointParameters {
              position -3.183115813655849e-12
              axis 1 0 0
            }
            device [
              LinearMotor {
                name "horizontal_right"
                maxForce 200
              }
            ]
            endPoint Solid {
              translation 0.17149999770839397 0.1229985098725328 -8.636324232010051e-05
              rotation -0.5989062939750435 0.8007919190861806 0.006599497204388628 5.492430793445233e-06
              children [
                DEF arm_r Shape {
                  appearance PBRAppearance {
                    roughness 1
                    metalness 0
                  }
                  geometry Box {
                    size 0.002 0.24 0.1
                  }
                }
                Solid {
                  translation -0.03 0 -0.05
                  children [
                    DEF arm_botom Shape {
                      appearance PBRAppearance {
                        roughness 1
                        metalness 0
                      }
                      geometry Box {
                        size 0.06 0.24 0.002
                      }
                    }
                  ]
                  boundingObject USE arm_botom
                  physics Physics {
                  }
                }
                Solid {
                  translation -0.015 0.12 0
                  children [
                    DEF arm_front Shape {
                      appearance PBRAppearance {
                        roughness 1
                        metalness 0
                      }
                      geometry Box {
                        size 0.03 0.001 0.1
                      }
                    }
                  ]
                  name "solid(1)"
                  boundingObject USE arm_front
                  physics Physics {
                  }
                }
              ]
              boundingObject USE arm_r
              physics Physics {
              }
            }
          }
          SliderJoint {
            jointParameters JointParameters {
              position -3.1831435052882546e-12
              axis 1 0 0
              maxStop -1
            }
            device [
              LinearMotor {
                name "horizontal_left"
                maxForce 200
              }
            ]
            endPoint Solid {
              translation -0.17100000058982304 0.12299992305086294 -5.1887132048816786e-05
              rotation -0.6388489785676387 -0.7688693381051885 -0.026681894699849877 1.9068196117125292e-06
              children [
                USE arm_r
                Solid {
                  translation 0.03 0 -0.048
                  children [
                    USE arm_botom
                  ]
                  boundingObject USE arm_botom
                  physics Physics {
                  }
                }
                Solid {
                  translation 0.015 0.12 0
                  children [
                    USE arm_front
                  ]
                  name "solid(1)"
                  boundingObject USE arm_front
                  physics Physics {
                  }
                }
              ]
              name "solid(1)"
              boundingObject USE arm_r
              physics Physics {
              }
            }
          }
          DistanceSensor {
            translation -4.89665e-14 6.74634e-14 0
            rotation 0 0 1 1.5708
            name "distance sensor in arm"
          }
          Lidar {
            translation -3.67318e-08 0.01 0.03
            rotation 0 0 1 1.5708
            physics Physics {
            }
          }
        ]
        name "solid(4)"
        boundingObject USE arm_h
        physics DEF arm_physics Physics {
        }
      }
    }
  ]
  boundingObject USE body
  physics Physics {
  }
  controller "IESL_new"
}
